<?xml version="1.0"?>
<robot xmlns:xacro="http://ros.org/wiki/xacro" name="husky_wheel">

	<xacro:macro name="myrobot_wheel" params="wheel_prefix *joint_pose">
		<link name="${wheel_prefix}_wheel">
			<inertial>
				<mass value="1.5" />
				<!-- <origin xyz="0.0 0.0 0.0" rpy="0 ${M_PI/2} ${M_PI/2}"/> -->
				<origin xyz="0.0 0.0 0.0" rpy="0 0 0"/> 
				<inertia ixx="0.15" ixy="0.0" ixz="0.0" iyy="0.15" iyz="0.0" izz="0.15"/>
			</inertial>
			<visual name="${wheel_prefix}_wheel_visual">
				<origin xyz="0.0 0.0 0.0" rpy="0 ${M_PI/2} ${M_PI/2}"/>
				<geometry>
					<cylinder radius="${wheel_rad}" length="${wheel_width}"/>
				</geometry>
			</visual>
			<collision>
                <origin xyz="0.0 0.0 0.0" rpy="0 ${M_PI/2} ${M_PI/2}"/>
				<geometry>
					<cylinder radius="${wheel_rad}" length="${wheel_width}"/>
				</geometry>
			</collision>
            <!-- Feature to see wheel rotating -->
            <visual name='front_left_wheel_bump'>
				<xacro:if value="${wheel_prefix.endswith('left')}">
                	<origin xyz="0.05 0.03 0.05" rpy=" 0 0 0"/>
				</xacro:if>
				<xacro:unless value="${wheel_prefix.endswith('left')}">
                	<origin xyz="0.05 -0.03 0.05" rpy=" 0 0 0"/>
				</xacro:unless>
                <geometry>
                    <sphere radius="0.02"/>
                </geometry>
            </visual>
		</link>

		<gazebo reference="${wheel_prefix}_wheel">
			<mu1 value="1"/>
			<mu2 value="1"/>
			<kp value="10000000.0" />
			<kd value="1.0" />
			<fdir1 value="1 0 0"/>
		</gazebo>

		<joint name="${wheel_prefix}_wheel_joint" type="continuous">
			<parent link="chassis"/>
			<child link="${wheel_prefix}_wheel"/>
			<xacro:insert_block name="joint_pose"/>
			<axis xyz="0 1 0" rpy="0 0 0" />
		</joint>

		<transmission name="${wheel_prefix}_wheel_transmission" type="SimpleTransmission">
			<type>transmission_interface/SimpleTransmission</type>
			<actuator name="${wheel_prefix}_wheel_motor">
				<mechanicalReduction>1</mechanicalReduction>
			</actuator>
			<joint name="${wheel_prefix}_wheel_joint">
				<hardwareInterface>hardware_interface/VelocityJointInterface</hardwareInterface>
			</joint>
		</transmission>

	</xacro:macro>
</robot>

